results/replay_selftest.log
=== lob_replay: NASDAQ TotalView-ITCH 5.0 day replay with ref::Market differential ===
run: 2026-09-21 04:15:12 local | cpu: Intel(R) Core(TM) Ultra 7 265H | compiler: g++ 16.1.0
command: lob_replay --selftest
source: git commit d191efd0d42adb9f10fdcfa47524371cd5f28866
file: lob_replay_selftest.itch
chunk 4,103 bytes | checkpoint every 100,000 messages | ladder budget 1 MB

[1] pre-scan (untimed, 0.1 s)
  bytes 48,059,287 | messages 1,500,044 | trailing bytes 0
  message counts by type:
     A       396,116    C        70,872    D       441,409    E       142,862
     F       132,407    I        14,888    P        15,013    Q        14,871
     R            40    S             4    U       157,376    X       114,186
  bad_length 0 | unknown type 0
  first message 09:30:00.018 | last message 13:40:11.166 (ET, from message timestamps) | timestamps out of order 0
  stock directory: 40 'R' messages for 40 stock_locates (0 repeated, 0 renamed) | locates with order messages: 40
  adds (A, F and the add half of U): 685,899 | peak resting orders, whole market: 30,000
  add prices that are not whole cents: 215,185 | outside $0.01..$1310.72: 306,804
  sizing (0.0 s): 40 books | grid $0.01: 31, grid $0.0001: 9 | ladder 1 MB | band ticks min 128 median 512 max 1,024
  adds the chosen ladders cover: 536,824 of 685,899 (78.266%); the other 149,075 rest in the overflow
  pools 37,280 order slots (1 MB) | id maps 81,920 slots (1 MB)

  named symbols (Stock Directory, and the 'Q' crosses NASDAQ ran):
  SYM0   locate 1     adds 17,371 | peak resting 860 | grid $0.01 | ladder 128 ticks from $99.6300
         opening cross: none in this file
         closing cross 100.5900 x 500 shares at 13:39:55.353
  SYM1   locate 1602  adds 17,392 | peak resting 826 | grid $0.0001 | ladder 256 ticks from $0.5060
         opening cross: none in this file
         closing cross 0.5126 x 500 shares at 13:40:06.760
  SYM5   locate 8006  adds 17,027 | peak resting 805 | grid $0.01 | ladder 128 ticks from $299999.6900
         opening cross: none in this file
         closing cross 300000.5800 x 500 shares at 13:39:58.114
  NOSUCH not in this day's stock directory

[2] replay, differential against ref::Market after every message and in full at every checkpoint | thread pinned to cpu 2
  checkpoint   1 | message        90,052 | 09:44:59.996 | books 40 | levels 4,794 | orders 5,853 | mismatches 0
  books at 09:45:00.000 ET (state after message 90,052):
  SYM0   locate 1     resting 160 | levels bid 70 ask 55 | overflow levels 38 | BBO 300009.0200 x 126 / 0.0013 x 350
         bid  300009.0200        126 (   1)   | ask       0.0013        350 (   1)
         bid  300008.8200        444 (   1)   | ask       0.0046        527 (   1)
         bid  300006.9700        395 (   1)   | ask       0.0093         80 (   1)
         bid  300000.5600        203 (   1)   | ask       0.0096      1,493 (   2)
         bid     101.0300      1,453 (   2)   | ask      99.6700        135 (   1)
  SYM1   locate 1602  resting 154 | levels bid 54 ask 61 | overflow levels 10 | BBO 300007.1300 x 74 / 0.0010 x 412
         bid  300007.1300         74 (   1)   | ask       0.0010        412 (   1)
         bid  300006.1300        117 (   1)   | ask       0.5060        839 (   1)
         bid  300005.9800        861 (   1)   | ask       0.5068         28 (   1)
         bid  300004.5600        601 (   1)   | ask       0.5069        832 (   1)
         bid  199999.9900      1,320 (   4)   | ask       0.5075        698 (   1)
  SYM5   locate 8006  resting 154 | levels bid 55 ask 50 | overflow levels 23 | BBO 300001.0700 x 703 / 0.0021 x 12
         bid  300001.0700        703 (   1)   | ask       0.0021         12 (   1)
         bid  300001.0300        409 (   1)   | ask       0.0083         54 (   1)
         bid  300000.9600        178 (   1)   | ask       0.0094        409 (   1)
         bid  300000.8300        844 (   2)   | ask  199999.9900      3,916 (   7)
         bid  300000.8200         19 (   1)   | ask  299999.6800        410 (   1)
  checkpoint   2 | message       100,000 | 09:46:38.743 | books 40 | levels 5,349 | orders 6,545 | mismatches 0
  checkpoint   3 | message       200,000 | 10:03:17.217 | books 40 | levels 9,790 | orders 13,488 | mismatches 0
  checkpoint   4 | message       300,000 | 10:19:58.191 | books 40 | levels 13,305 | orders 20,083 | mismatches 0
  checkpoint   5 | message       400,000 | 10:36:38.988 | books 40 | levels 16,965 | orders 27,538 | mismatches 0
  checkpoint   6 | message       500,000 | 10:53:16.909 | books 40 | levels 17,800 | orders 29,978 | mismatches 0
  checkpoint   7 | message       600,000 | 11:09:57.563 | books 40 | levels 17,975 | orders 29,987 | mismatches 0
  checkpoint   8 | message       700,000 | 11:26:34.783 | books 40 | levels 18,040 | orders 29,991 | mismatches 0
  checkpoint   9 | message       800,000 | 11:43:18.299 | books 40 | levels 17,960 | orders 29,993 | mismatches 0
  checkpoint  10 | message       900,000 | 12:00:00.342 | books 40 | levels 17,911 | orders 29,997 | mismatches 0
  checkpoint  11 | message     1,000,000 | 12:16:41.180 | books 40 | levels 17,867 | orders 29,999 | mismatches 0
  checkpoint  12 | message     1,100,000 | 12:33:24.893 | books 40 | levels 17,929 | orders 29,997 | mismatches 0
  checkpoint  13 | message     1,200,000 | 12:50:02.425 | books 40 | levels 17,938 | orders 29,997 | mismatches 0
  checkpoint  14 | message     1,300,000 | 13:06:45.830 | books 40 | levels 17,973 | orders 30,000 | mismatches 0
  checkpoint  15 | message     1,400,000 | 13:23:27.581 | books 40 | levels 17,987 | orders 29,995 | mismatches 0
  checkpoint  16 | message     1,500,000 | 13:40:10.690 | books 40 | levels 17,877 | orders 29,999 | mismatches 0
  checkpoint  17 | message     1,500,044 | 13:40:11.166 | books 40 | levels 17,878 | orders 29,997 | mismatches 0 (end of file)

[3] totals
  messages: pass 1 1,500,044 | pass 2 1,500,044 | trailing bytes 0
  chunks 11,714 | chunk boundaries inside a message 11,352 (inside its length prefix 368)
  books: 40 | resting orders at end of file: 29,997
  bad_length: pre-scan 0, dispatch 0 | dropped_out_of_band 0 | unknown order id 0
  adds on the ladder 536,824 | in the overflow 149,075 (21.734% of 685,899; sizing predicted 149,075)
  reference applied: A 396,116  F 132,407  E 142,862  C 70,872  X 114,186  D 441,409  U 157,376
  reference anomalies: unknown ref 0 | duplicate ref 0 | over-execution 0 | locate mismatch 0 | bad side 0 | bad length 0
  checkpoints 17 | book comparisons 680 | levels compared 265,338 | orders compared in queue order 433,437 | mismatches 0
  after every order message: 1,455,228 messages checked (resting count and BBO of the book, the orders and price levels the message touched) | orders compared 1,612,604 | levels compared 1,612,604 | mismatches 0
  dispatch time 0.318 s for 1,500,044 messages (211.9 ns/msg) - differential run: not a measurement
  final books (end of file):
  SYM0   locate 1     resting 753 | levels bid 155 ask 142 | overflow levels 116 | BBO 429496.7295 x 195 / 0.0003 x 867
         bid  429496.7295        195 (   1)   | ask       0.0003        867 (   1)
         bid  429496.7294        434 (   2)   | ask       0.0010        299 (   1)
         bid  429496.7293        314 (   2)   | ask       0.0011        297 (   1)
         bid  300009.4000        276 (   1)   | ask       0.0016        203 (   1)
         bid  300008.4400        100 (   1)   | ask       0.0021        576 (   1)
  SYM1   locate 1602  resting 796 | levels bid 180 ask 176 | overflow levels 41 | BBO 429496.7295 x 125 / 0.0025 x 679
         bid  429496.7295        125 (   1)   | ask       0.0025        679 (   1)
         bid  429496.7293        665 (   2)   | ask       0.0031        147 (   1)
         bid  300007.1200        690 (   1)   | ask       0.0035        770 (   1)
         bid  300007.0100        166 (   1)   | ask       0.0042        295 (   1)
         bid  300004.3900        737 (   1)   | ask       0.0043        824 (   1)
